<?xml version="1.0"?>
<robot xmlns:xacro="http://wiki.ros.org/xacro">
  <!-- include helper xacros -->
  <xacro:include filename="$(find kuka_resources)/urdf/common_constants.xacro"/>
  <xacro:include filename="$(find kuka_resources)/urdf/common_materials.xacro"/>
  <!-- NOTE: inertial values below are reasonable placeholders. Replace with measured/spec values for accurate simulation. -->
  <xacro:macro name="kuka_kr6_r900_sixx_robot" params="prefix package_name *origin">
    <!-- links - main serial chain -->
    <link name="world"/>

    <link name="${prefix}base_link">
      <inertial>
        <origin xyz="0 0 0" rpy="0 0 0"/>
        <mass value="12.0"/>
        <inertia ixx="0.24" iyy="0.24" izz="0.24" ixy="0" ixz="0" iyz="0"/>
      </inertial>
      <visual>
        <origin xyz="0 0 0" rpy="0 0 0"/>
        <geometry>
          <mesh filename="package://${package_name}/meshes/kr6_r900_sixx/visual/base_link.dae"/>
        </geometry>
        <xacro:material_kuka_pedestal/>
      </visual>
      <collision>
        <origin xyz="0 0 0" rpy="0 0 0"/>
        <geometry>
          <mesh filename="package://${package_name}/meshes/kr6_r900_sixx/collision/base_link.stl"/>
        </geometry>
      </collision>
    </link>

    <link name="${prefix}link_1">
      <inertial>
        <origin xyz="0 0 0" rpy="0 0 0"/>
        <mass value="8.0"/>
        <inertia ixx="0.16" iyy="0.16" izz="0.16" ixy="0" ixz="0" iyz="0"/>
      </inertial>
      <visual>
        <origin xyz="0 0 0" rpy="0 0 0"/>
        <geometry>
          <mesh filename="package://${package_name}/meshes/kr6_r900_sixx/visual/link_1.dae"/>
        </geometry>
        <xacro:material_kuka_orange/>
      </visual>
      <collision>
        <origin xyz="0 0 0" rpy="0 0 0"/>
        <geometry>
          <mesh filename="package://${package_name}/meshes/kr6_r900_sixx/collision/link_1.stl"/>
        </geometry>
      </collision>
    </link>

    <link name="${prefix}link_2">
      <inertial>
        <origin xyz="0 0 0" rpy="0 0 0"/>
        <mass value="6.0"/>
        <inertia ixx="0.12" iyy="0.12" izz="0.12" ixy="0" ixz="0" iyz="0"/>
      </inertial>
      <visual>
        <origin xyz="0 0 0" rpy="0 0 0"/>
        <geometry>
          <mesh filename="package://${package_name}/meshes/kr6_r900_sixx/visual/link_2.dae"/>
        </geometry>
        <xacro:material_kuka_orange/>
      </visual>
      <collision>
        <origin xyz="0 0 0" rpy="0 0 0"/>
        <geometry>
          <mesh filename="package://${package_name}/meshes/kr6_r900_sixx/collision/link_2.stl"/>
        </geometry>
      </collision>
    </link>

    <link name="${prefix}link_3">
      <inertial>
        <origin xyz="0 0 0" rpy="0 0 0"/>
        <mass value="4.0"/>
        <inertia ixx="0.08" iyy="0.08" izz="0.08" ixy="0" ixz="0" iyz="0"/>
      </inertial>
      <visual>
        <origin xyz="0 0 0" rpy="0 0 0"/>
        <geometry>
          <mesh filename="package://${package_name}/meshes/kr6_r900_sixx/visual/link_3.dae"/>
        </geometry>
        <xacro:material_kuka_orange/>
      </visual>
      <collision>
        <origin xyz="0 0 0" rpy="0 0 0"/>
        <geometry>
          <mesh filename="package://${package_name}/meshes/kr6_r900_sixx/collision/link_3.stl"/>
        </geometry>
      </collision>
    </link>

    <link name="${prefix}link_4">
      <inertial>
        <origin xyz="0 0 0" rpy="0 0 0"/>
        <mass value="3.0"/>
        <inertia ixx="0.06" iyy="0.06" izz="0.06" ixy="0" ixz="0" iyz="0"/>
      </inertial>
      <visual>
        <origin xyz="0 0 0" rpy="0 0 0"/>
        <geometry>
          <mesh filename="package://${package_name}/meshes/kr6_r900_sixx/visual/link_4.dae"/>
        </geometry>
        <xacro:material_kuka_orange/>
      </visual>
      <collision>
        <origin xyz="0 0 0" rpy="0 0 0"/>
        <geometry>
          <mesh filename="package://${package_name}/meshes/kr6_r900_sixx/collision/link_4.stl"/>
        </geometry>
      </collision>
    </link>

    <link name="${prefix}link_5">
      <inertial>
        <origin xyz="0 0 0" rpy="0 0 0"/>
        <mass value="2.5"/>
        <inertia ixx="0.05" iyy="0.05" izz="0.05" ixy="0" ixz="0" iyz="0"/>
      </inertial>
      <visual>
        <origin xyz="0 0 0" rpy="0 0 0"/>
        <geometry>
          <mesh filename="package://${package_name}/meshes/kr6_r900_sixx/visual/link_5.dae"/>
        </geometry>
        <xacro:material_kuka_orange/>
      </visual>
      <collision>
        <origin xyz="0 0 0" rpy="0 0 0"/>
        <geometry>
          <mesh filename="package://${package_name}/meshes/kr6_r900_sixx/collision/link_5.stl"/>
        </geometry>
      </collision>
    </link>

    <link name="${prefix}link_6">
      <inertial>
        <origin xyz="0 0 0" rpy="0 0 0"/>
        <mass value="1.5"/>
        <inertia ixx="0.03" iyy="0.03" izz="0.03" ixy="0" ixz="0" iyz="0"/>
      </inertial>
      <visual>
        <origin xyz="0 0 0" rpy="0 0 0"/>
        <geometry>
          <mesh filename="package://${package_name}/meshes/kr6_r900_sixx/visual/link_6.dae"/>
        </geometry>
        <xacro:material_kuka_pedestal/>
      </visual>
      <collision>
        <origin xyz="0 0 0" rpy="0 0 0"/>
        <geometry>
          <mesh filename="package://${package_name}/meshes/kr6_r900_sixx/collision/link_6.stl"/>
        </geometry>
      </collision>
    </link>

    <!-- Following REP199, this frame shall be use to attach EEF or other equipment -->
    <link name="${prefix}flange">
      <inertial>
        <origin xyz="0 0 0" rpy="0 0 0"/>
        <mass value="0.5"/>
        <inertia ixx="0.01" iyy="0.01" izz="0.01" ixy="0" ixz="0" iyz="0"/>
      </inertial>
    </link>

    <joint name="${prefix}world-base_link" type="fixed">
      <parent link="world"/>
      <child link="${prefix}base_link"/>
      <xacro:insert_block name="origin"/>
    </joint>

    <joint name="${prefix}joint_1" type="revolute">
      <origin xyz="0 0 0.400" rpy="0 0 0"/>
      <parent link="${prefix}base_link"/>
      <child link="${prefix}link_1"/>
      <axis xyz="0 0 -1"/>
      <limit effort="0" lower="${-radians(170)}" upper="${radians(170)}" velocity="${radians(360)}"/>
    </joint>

    <joint name="${prefix}joint_2" type="revolute">
      <origin xyz="0.025 0 0" rpy="0 0 0"/>
      <parent link="${prefix}link_1"/>
      <child link="${prefix}link_2"/>
      <axis xyz="0 1 0"/>
      <limit effort="0" lower="${-radians(190)}" upper="${radians(45)}" velocity="${radians(300)}"/>
    </joint>

    <joint name="${prefix}joint_3" type="revolute">
      <origin xyz="0.455 0 0" rpy="0 0 0"/>
      <parent link="${prefix}link_2"/>
      <child link="${prefix}link_3"/>
      <axis xyz="0 1 0"/>
      <limit effort="0" lower="${-radians(120)}" upper="${radians(156)}" velocity="${radians(360)}"/>
    </joint>

    <joint name="${prefix}joint_4" type="revolute">
      <origin xyz="0 0 0.035" rpy="0 0 0"/>
      <parent link="${prefix}link_3"/>
      <child link="${prefix}link_4"/>
      <axis xyz="-1 0 0"/>
      <limit effort="0" lower="${-radians(185)}" upper="${radians(185)}" velocity="${radians(381)}"/>
    </joint>

    <joint name="${prefix}joint_5" type="revolute">
      <origin xyz="0.420 0 0" rpy="0 0 0"/>
      <parent link="${prefix}link_4"/>
      <child link="${prefix}link_5"/>
      <axis xyz="0 1 0"/>
      <limit effort="0" lower="${-radians(120)}" upper="${radians(120)}" velocity="${radians(388)}"/>
    </joint>

    <joint name="${prefix}joint_6" type="revolute">
      <origin xyz="0.080 0 0" rpy="0 0 0"/>
      <parent link="${prefix}link_5"/>
      <child link="${prefix}link_6"/>
      <axis xyz="-1 0 0"/>
      <limit effort="0" lower="${-radians(350)}" upper="${radians(350)}" velocity="${radians(615)}"/>
    </joint>

    <joint name="${prefix}joint_6-flange" type="fixed">
      <parent link="${prefix}link_6"/>
      <child link="${prefix}flange"/>
      <origin xyz="0 0 0" rpy="0 0 0"/>
    </joint>

    <!-- ROS base_link to KUKA $ROBROOT coordinate system transform -->
    <link name="${prefix}base">
      <inertial>
        <origin xyz="0 0 0" rpy="0 0 0"/>
        <mass value="1.0"/>
        <inertia ixx="0.02" iyy="0.02" izz="0.02" ixy="0" ixz="0" iyz="0"/>
      </inertial>
    </link>

    <joint name="${prefix}base_link-base" type="fixed">
      <origin xyz="0 0 0" rpy="0 0 0"/>
      <parent link="${prefix}base_link"/>
      <child link="${prefix}base"/>
    </joint>

    <!-- This frame corresponds to the $TOOL coordinate system in KUKA KRC controllers -->
    <link name="${prefix}tool0">
      <inertial>
        <origin xyz="0 0 0" rpy="0 0 0"/>
        <mass value="0.2"/>
        <inertia ixx="0.004" iyy="0.004" izz="0.004" ixy="0" ixz="0" iyz="0"/>
      </inertial>
    </link>

    <joint name="${prefix}flange-tool0" type="fixed">
      <parent link="${prefix}flange"/>
      <child link="${prefix}tool0"/>
      <origin xyz="0 0 0" rpy="0 ${radians(90)} 0"/>
    </joint>

  </xacro:macro>
</robot>
